<?xml version="1.0"?>
<robot xmlns:xacro="http://www.ros.org/wiki/xacro">

  <xacro:include filename="inertial_macros.xacro"/>
  <xacro:include filename="colors.xacro"/>

  <!-- ============================================================ -->
  <!--  Properties                                                   -->
  <!-- ============================================================ -->
  <xacro:property name="chassis_length"  value="0.30"/>
  <xacro:property name="chassis_width"   value="0.30"/>
  <xacro:property name="chassis_height"  value="0.20"/>
  <xacro:property name="chassis_mass"    value="5.0"/>

  <xacro:property name="wheel_radius"    value="0.05"/>
  <xacro:property name="wheel_thickness" value="0.04"/>
  <xacro:property name="wheel_mass"      value="0.5"/>
  <xacro:property name="wheel_offset_y"  value="${chassis_width/2 + wheel_thickness/2}"/>
  <xacro:property name="wheel_offset_z"  value="0.0"/>

  <xacro:property name="caster_radius"   value="${wheel_radius}"/>
  <xacro:property name="caster_mass"     value="0.1"/>

  <!-- ============================================================ -->
  <!--  Base link (footprint on the ground)                          -->
  <!-- ============================================================ -->
  <link name="base_link"/>

  <!-- ============================================================ -->
  <!--  Chassis                                                      -->
  <!-- ============================================================ -->
  <joint name="chassis_joint" type="fixed">
    <parent link="base_link"/>
    <child  link="chassis"/>
    <origin xyz="${-chassis_length*3/4} 0 ${wheel_radius}" rpy="0 0 0"/>
  </joint>

  <link name="chassis">
    <visual>
      <origin xyz="${chassis_length/2} 0 ${chassis_height/4}" rpy="0 0 0"/>
      <geometry>
        <box size="${chassis_length} ${chassis_width} ${chassis_height}"/>
      </geometry>
      <material name="orange"/>
    </visual>
    <collision>
      <origin xyz="${chassis_length/2} 0 ${chassis_height/4}" rpy="0 0 0"/>
      <geometry>
        <box size="${chassis_length} ${chassis_width} ${chassis_height}"/>
      </geometry>
    </collision>
    <xacro:inertial_box mass="${chassis_mass}" x="${chassis_length}" y="${chassis_width}" z="${chassis_height}">
      <origin xyz="${chassis_length/2} 0 ${chassis_height/2}" rpy="0 0 0"/>
    </xacro:inertial_box>
  </link>

  <gazebo reference="chassis">
    <material>Gazebo/Orange</material>
  </gazebo>

  <!-- ============================================================ -->
  <!--  Drive wheels (left / right)                                  -->
  <!-- ============================================================ -->
  <xacro:macro name="drive_wheel" params="prefix y_reflect">
    <joint name="${prefix}_wheel_joint" type="continuous">
      <parent link="base_link"/>
      <child  link="${prefix}_wheel"/>
      <origin xyz="0 ${y_reflect * wheel_offset_y} ${wheel_offset_z}" rpy="${-pi/2} 0 0"/>
      <axis xyz="0 0 1"/>
    </joint>

    <link name="${prefix}_wheel">
      <visual>
        <geometry>
          <cylinder radius="${wheel_radius}" length="${wheel_thickness}"/>
        </geometry>
        <material name="dark_grey"/>
      </visual>
      <collision>
        <geometry>
          <cylinder radius="${wheel_radius}" length="${wheel_thickness}"/>
        </geometry>
      </collision>
      <xacro:inertial_cylinder mass="${wheel_mass}" length="${wheel_thickness}" radius="${wheel_radius}">
        <origin xyz="0 0 0" rpy="0 0 0"/>
      </xacro:inertial_cylinder>
    </link>

    <gazebo reference="${prefix}_wheel">
      <material>Gazebo/DarkGrey</material>
      <mu1>1.0</mu1>
      <mu2>1.0</mu2>
    </gazebo>
  </xacro:macro>

  <xacro:drive_wheel prefix="left"  y_reflect="1"/>
  <xacro:drive_wheel prefix="right" y_reflect="-1"/>

  <!-- ============================================================ -->
  <!--  Caster wheel (rear, frictionless ball)                       -->
  <!-- ============================================================ -->
  <joint name="caster_wheel_joint" type="fixed">
    <parent link="chassis"/>
    <child  link="caster_wheel"/>
    <origin xyz="${caster_radius} 0 ${-wheel_radius}" rpy="0 0 0"/>
  </joint>

  <link name="caster_wheel">
    <visual>
      <geometry>
        <sphere radius="${caster_radius}"/>
      </geometry>
      <material name="white"/>
    </visual>
    <collision>
      <geometry>
        <sphere radius="${caster_radius}"/>
      </geometry>
    </collision>
    <xacro:inertial_sphere mass="${caster_mass}" radius="${caster_radius}">
      <origin xyz="0 0 0" rpy="0 0 0"/>
    </xacro:inertial_sphere>
  </link>

  <gazebo reference="caster_wheel">
    <material>Gazebo/White</material>
    <mu1>0.001</mu1>
    <mu2>0.001</mu2>
  </gazebo>

</robot>
